Workbook

Sheet MAIN
A1: Listing_ID | B1: Raw_Title | C1: Locality_Text | D1: Asset_Type_Raw | E1: Configuration_Raw | F1: Area_Value | G1: Area_Unit | H1: Price_Value | I1: Price_Unit | J1: Price_Frequency | K1: Status | L1: Remarks | M1: Micro_Market | N1: Standard_Asset_Class | O1: Standard_BHK | P1: Vertical | Q1: Price_INR | R1: Area_Sqft | S1: Resale_PPSF | T1: Notes | U1: Micro Market | V1: Asset | W1: Resale N | X1: Median Resale PPSF | Y1: LTR_INR_per_Sqft_Month | Z1: LTR N | AA1: Median LTR INR/sqft/month | AB1: Implied Gross Rental Yield % | AC1: Median STR ADR
A2: K0001 | B2: NA Plot for sale in Central Karjat | C2: Central Karjat | D2: NA Plot | E2: NA | F2: 3139 | G2: sqft | H2: 29.73 | I2: Lakh | J2: One-time | K2: Active | M2: =_xlfn.XLOOKUP(TRIM(C2),MAPPING!A:A,MAPPING!B:B,"CHECK") -> Karjat Town | N2: =_xlfn.XLOOKUP(D2,MAPPING!G:G,MAPPING!H:H,"CHECK") -> Plot | O2: =_xlfn.XLOOKUP(E2,MAPPING!J:J,MAPPING!K:K,"CHECK") -> NA | P2: =_xlfn.XLOOKUP(J2,MAPPING!M:M,MAPPING!N:N,"CHECK") -> Resale | Q2: =IF(I2="INR",H2,IF(I2="Lakh",H2*100000,IF(I2="Crore",H2*10000000,IF(I2="Thousand",H2*1000,"")))) -> 2973000 | R2: =IF(G2="sqft",F2,IF(G2="sqyd",F2*9,IF(G2="acre",F2*43560,IF(G2="guntha",F2*1089,IF(G2="hectare",F2*107639.1,""))))) -> 3139 | S2: =IF(AND(P2="Resale",R2>0),Q2/R2,"") -> 947.11692 | U2: Karjat Town | V2: Villa | W2: =COUNTIFS($M$2:$M$209,U2,$N$2:$N$209,V2,$P$2:$P$209,"Resale") -> 11 | X2: {=IFERROR(MEDIAN(_xlfn._xlws.FILTER($S$2:$S$209,($M$2:$M$209=U2)*($N$2:$N$209=V2)*($P$2:$P$209="Resale")*($S$2:$S$209<>""))),"")} -> 4641.194 | Y2: =IF(AND(P2="Long Term Rental",R2>0),Q2/R2,"") | Z2: =COUNTIFS($M$2:$M$209,U2,$N$2:$N$209,V2,$P$2:$P$209,"Long Term Rental") -> 8 | AA2: {=IF(Z2=0,"",MEDIAN(_xlfn._xlws.FILTER($Y$2:$Y$209,($M$2:$M$209=U2)*($N$2:$N$209=V2)*($P$2:$P$209="Long Term Rental")*($Y$2:$Y$209<>""),"")))} -> 14.651858 | AB2: =IF(AND(V2="Villa",X2<>"",AA2<>""),(AA2*12/X2)*100,"") -> 3.7882987 | AC2: {=IFERROR(MEDIAN(_xlfn._xlws.FILTER($Q$2:$Q$209,($M$2:$M$209=U2)*($P$2:$P$209="Short Term Rental")*($Q$2:$Q$209<>""))),"")} -> 5650
A3: K0002 | B3: 4BHK Bungalow for sale in Karjat | C3: Karjat | D3: Bungalow | E3: 4BHK | F3: 2495 | G3: sqft | I3: Crore | J3: One-time | K3: Price on Request | M3: =_xlfn.XLOOKUP(TRIM(C3),MAPPING!A:A,MAPPING!B:B,"CHECK") -> Karjat Town | N3: =_xlfn.XLOOKUP(D3,MAPPING!G:G,MAPPING!H:H,"CHECK") -> Villa | O3: =_xlfn.XLOOKUP(E3,MAPPING!J:J,MAPPING!K:K,"CHECK") -> 4 BHK | P3: =_xlfn.XLOOKUP(J3,MAPPING!M:M,MAPPING!N:N,"CHECK") -> Resale | Q3: =IF(I3="INR",H3,IF(I3="Lakh",H3*100000,IF(I3="Crore",H3*10000000,IF(I3="Thousand",H3*1000,"")))) -> 0 | R3: =IF(G3="sqft",F3,IF(G3="sqyd",F3*9,IF(G3="acre",F3*43560,IF(G3="guntha",F3*1089,IF(G3="hectare",F3*107639.1,""))))) -> 2495 | S3: =IF(AND(P3="Resale",R3>0),Q3/R3,"") -> 0 | U3: Karjat Town | V3: Plot | W3: =COUNTIFS($M$2:$M$209,U3,$N$2:$N$209,V3,$P$2:$P$209,"Resale") -> 8 | X3: {=IFERROR(MEDIAN(_xlfn._xlws.FILTER($S$2:$S$209,($M$2:$M$209=U3)*($N$2:$N$209=V3)*($P$2:$P$209="Resale")*($S$2:$S$209<>""))),"")} -> 947.11692 | Y3: =IF(AND(P3="Long Term Rental",R3>0),Q3/R3,"") | Z3: =COUNTIFS($M$2:$M$209,U3,$N$2:$N$209,V3,$P$2:$P$209,"Long Term Rental") -> 0 | AA3: {=IF(Z3=0,"",MEDIAN(_xlfn._xlws.FILTER($Y$2:$Y$209,($M$2:$M$209=U3)*($N$2:$N$209=V3)*($P$2:$P$209="Long Term Rental")*($Y$2:$Y$209<>""),"")))} | AB3: =IF(AND(V3="Villa",X3<>"",AA3<>""),(AA3*12/X3)*100,"") | AC3: {=IFERROR(MEDIAN(_xlfn._xlws.FILTER($Q$2:$Q$209,($M$2:$M$209=U3)*($P$2:$P$209="Short Term Rental")*($Q$2:$Q$209<>""))),"")} -> 5650
A4: K0003 | B4: Plot for sale in Karjat Station Road | C4: Karjat Station Road | D4: Plot | E4: NA | F4: 1.17 | G4: acre | H4: 4.18 | I4: Crore | J4: One-time | K4: Sold | M4: =_xlfn.XLOOKUP(TRIM(C4),MAPPING!A:A,MAPPING!B:B,"CHECK") -> Karjat Town | N4: =_xlfn.XLOOKUP(D4,MAPPING!G:G,MAPPING!H:H,"CHECK") -> Plot | O4: =_xlfn.XLOOKUP(E4,MAPPING!J:J,MAPPING!K:K,"CHECK") -> NA | P4: =_xlfn.XLOOKUP(J4,MAPPING!M:M,MAPPING!N:N,"CHECK") -> Resale | Q4: =IF(I4="INR",H4,IF(I4="Lakh",H4*100000,IF(I4="Crore",H4*10000000,IF(I4="Thousand",H4*1000,"")))) -> 41800000 | R4: =IF(G4="sqft",F4,IF(G4="sqyd",F4*9,IF(G4="acre",F4*43560,IF(G4="guntha",F4*1089,IF(G4="hectare",F4*107639.1,""))))) -> 50965.2 | S4: =IF(AND(P4="Resale",R4>0),Q4/R4,"") -> 820.16749 | U4: Karjat Town | V4: Farmland | W4: =COUNTIFS($M$2:$M$209,U4,$N$2:$N$209,V4,$P$2:$P$209,"Resale") -> 5 | X4: {=IFERROR(MEDIAN(_xlfn._xlws.FILTER($S$2:$S$209,($M$2:$M$209=U4)*($N$2:$N$209=V4)*($P$2:$P$209="Resale")*($S$2:$S$209<>""))),"")} -> 148.72041 | Y4: =IF(AND(P4="Long Term Rental",R4>0),Q4/R4,"") | Z4: =COUNTIFS($M$2:$M$209,U4,$N$2:$N$209,V4,$P$2:$P$209,"Long Term Rental") -> 0 | AA4: {=IF(Z4=0,"",MEDIAN(_xlfn._xlws.FILTER($Y$2:$Y$209,($M$2:$M$209=U4)*($N$2:$N$209=V4)*($P$2:$P$209="Long Term Rental")*($Y$2:$Y$209<>""),"")))} | AB4: =IF(AND(V4="Villa",X4<>"",AA4<>""),(AA4*12/X4)*100,"") | AC4: {=IFERROR(MEDIAN(_xlfn._xlws.FILTER($Q$2:$Q$209,($M$2:$M$209=U4)*($P$2:$P$209="Short Term Rental")*($Q$2:$Q$209<>""))),"")} -> 5650
A5: K0004 | B5: Land Parcel for sale in Karjat Town | C5: Karjat Town | D5: Land Parcel | E5: NA | F5: 5.2 | G5: guntha | H5: 55.77 | I5: Lakh | J5: One-time | K5: Active | M5: =_xlfn.XLOOKUP(TRIM(C5),MAPPING!A:A,MAPPING!B:B,"CHECK") -> Karjat Town | N5: =_xlfn.XLOOKUP(D5,MAPPING!G:G,MAPPING!H:H,"CHECK") -> Plot | O5: =_xlfn.XLOOKUP(E5,MAPPING!J:J,MAPPING!K:K,"CHECK") -> NA | P5: =_xlfn.XLOOKUP(J5,MAPPING!M:M,MAPPING!N:N,"CHECK") -> Resale | Q5: =IF(I5="INR",H5,IF(I5="Lakh",H5*100000,IF(I5="Crore",H5*10000000,IF(I5="Thousand",H5*1000,"")))) -> 5577000 | R5: =IF(G5="sqft",F5,IF(G5="sqyd",F5*9,IF(G5="acre",F5*43560,IF(G5="guntha",F5*1089,IF(G5="hectare",F5*107639.1,""))))) -> 5662.8 | S5: =IF(AND(P5="Resale",R5>0),Q5/R5,"") -> 984.84848 | U5: Neral | V5: Villa | W5: =COUNTIFS($M$2:$M$209,U5,$N$2:$N$209,V5,$P$2:$P$209,"Resale") -> 15 | X5: {=IFERROR(MEDIAN(_xlfn._xlws.FILTER($S$2:$S$209,($M$2:$M$209=U5)*($N$2:$N$209=V5)*($P$2:$P$209="Resale")*($S$2:$S$209<>""))),"")} -> 3642.7759 | Y5: =IF(AND(P5="Long Term Rental",R5>0),Q5/R5,"") | Z5: =COUNTIFS($M$2:$M$209,U5,$N$2:$N$209,V5,$P$2:$P$209,"Long Term Rental") -> 9 | AA5: {=IF(Z5=0,"",MEDIAN(_xlfn._xlws.FILTER($Y$2:$Y$209,($M$2:$M$209=U5)*($N$2:$N$209=V5)*($P$2:$P$209="Long Term Rental")*($Y$2:$Y$209<>""),"")))} -> 12.890874 | AB5: =IF(AND(V5="Villa",X5<>"",AA5<>""),(AA5*12/X5)*100,"") -> 4.2465004 | AC5: {=IFERROR(MEDIAN(_xlfn._xlws.FILTER($Q$2:$Q$209,($M$2:$M$209=U5)*($P$2:$P$209="Short Term Rental")*($Q$2:$Q$209<>""))),"")} -> 5000
A6: K0005 | B6: Farm for sale in Karjat West | C6: Karjat West | D6: Farm | E6: NA | F6: 2.3 | G6: acre | H6: 1.49 | I6: Crore | J6: One-time | K6: Active | M6: =_xlfn.XLOOKUP(TRIM(C6),MAPPING!A:A,MAPPING!B:B,"CHECK") -> Karjat Town | N6: =_xlfn.XLOOKUP(D6,MAPPING!G:G,MAPPING!H:H,"CHECK") -> Farmland | O6: =_xlfn.XLOOKUP(E6,MAPPING!J:J,MAPPING!K:K,"CHECK") -> NA | P6: =_xlfn.XLOOKUP(J6,MAPPING!M:M,MAPPING!N:N,"CHECK") -> Resale | Q6: =IF(I6="INR",H6,IF(I6="Lakh",H6*100000,IF(I6="Crore",H6*10000000,IF(I6="Thousand",H6*1000,"")))) -> 14900000 | R6: =IF(G6="sqft",F6,IF(G6="sqyd",F6*9,IF(G6="acre",F6*43560,IF(G6="guntha",F6*1089,IF(G6="hectare",F6*107639.1,""))))) -> 100188 | S6: =IF(AND(P6="Resale",R6>0),Q6/R6,"") -> 148.72041 | U6: Neral | V6: Plot | W6: =COUNTIFS($M$2:$M$209,U6,$N$2:$N$209,V6,$P$2:$P$209,"Resale") -> 5 | X6: {=IFERROR(MEDIAN(_xlfn._xlws.FILTER($S$2:$S$209,($M$2:$M$209=U6)*($N$2:$N$209=V6)*($P$2:$P$209="Resale")*($S$2:$S$209<>""))),"")} -> 861.89985 | Y6: =IF(AND(P6="Long Term Rental",R6>0),Q6/R6,"") | Z6: =COUNTIFS($M$2:$M$209,U6,$N$2:$N$209,V6,$P$2:$P$209,"Long Term Rental") -> 0 | AA6: {=IF(Z6=0,"",MEDIAN(_xlfn._xlws.FILTER($Y$2:$Y$209,($M$2:$M$209=U6)*($N$2:$N$209=V6)*($P$2:$P$209="Long Term Rental")*($Y$2:$Y$209<>""),"")))} | AB6: =IF(AND(V6="Villa",X6<>"",AA6<>""),(AA6*12/X6)*100,"") | AC6: {=IFERROR(MEDIAN(_xlfn._xlws.FILTER($Q$2:$Q$209,($M$2:$M$209=U6)*($P$2:$P$209="Short Term Rental")*($Q$2:$Q$209<>""))),"")} -> 5000
A7: K0006 | B7: 2BHK Independent House for sale in Karjat | C7: Karjat | D7: Independent House | E7: 2BHK | F7: 901 | G7: sqft | H7: 43.87 | I7: Lakh | J7: One-time | K7: Active | M7: =_xlfn.XLOOKUP(TRIM(C7),MAPPING!A:A,MAPPING!B:B,"CHECK") -> Karjat Town | N7: =_xlfn.XLOOKUP(D7,MAPPING!G:G,MAPPING!H:H,"CHECK") -> Villa | O7: =_xlfn.XLOOKUP(E7,MAPPING!J:J,MAPPING!K:K,"CHECK") -> 2 BHK | P7: =_xlfn.XLOOKUP(J7,MAPPING!M:M,MAPPING!N:N,"CHECK") -> Resale | Q7: =IF(I7="INR",H7,IF(I7="Lakh",H7*100000,IF(I7="Crore",H7*10000000,IF(I7="Thousand",H7*1000,"")))) -> 4387000 | R7: =IF(G7="sqft",F7,IF(G7="sqyd",F7*9,IF(G7="acre",F7*43560,IF(G7="guntha",F7*1089,IF(G7="hectare",F7*107639.1,""))))) -> 901 | S7: =IF(AND(P7="Resale",R7>0),Q7/R7,"") -> 4869.0344 | U7: Neral | V7: Farmland | W7: =COUNTIFS($M$2:$M$209,U7,$N$2:$N$209,V7,$P$2:$P$209,"Resale") -> 5 | X7: {=IFERROR(MEDIAN(_xlfn._xlws.FILTER($S$2:$S$209,($M$2:$M$209=U7)*($N$2:$N$209=V7)*($P$2:$P$209="Resale")*($S$2:$S$209<>""))),"")} -> 152.70219 | Y7: =IF(AND(P7="Long Term Rental",R7>0),Q7/R7,"") | Z7: =COUNTIFS($M$2:$M$209,U7,$N$2:$N$209,V7,$P$2:$P$209,"Long Term Rental") -> 0 | AA7: {=IF(Z7=0,"",MEDIAN(_xlfn._xlws.FILTER($Y$2:$Y$209,($M$2:$M$209=U7)*($N$2:$N$209=V7)*($P$2:$P$209="Long Term Rental")*($Y$2:$Y$209<>""),"")))} | AB7: =IF(AND(V7="Villa",X7<>"",AA7<>""),(AA7*12/X7)*100,"") | AC7: {=IFERROR(MEDIAN(_xlfn._xlws.FILTER($Q$2:$Q$209,($M$2:$M$209=U7)*($P$2:$P$209="Short Term Rental")*($Q$2:$Q$209<>""))),"")} -> 5000
A8: K0007 | B8: Two BHK Farmhouse for sale in Karjat Town | C8: Karjat Town | D8: Farmhouse | E8: Two BHK | F8: 1675 | G8: sqft | H8: 77.74 | I8: Lakh | J8: One-time | K8: Active | M8: =_xlfn.XLOOKUP(TRIM(C8),MAPPING!A:A,MAPPING!B:B,"CHECK") -> Karjat Town | N8: =_xlfn.XLOOKUP(D8,MAPPING!G:G,MAPPING!H:H,"CHECK") -> Villa | O8: =_xlfn.XLOOKUP(E8,MAPPING!J:J,MAPPING!K:K,"CHECK") -> 2 BHK | P8: =_xlfn.XLOOKUP(J8,MAPPING!M:M,MAPPING!N:N,"CHECK") -> Resale | Q8: =IF(I8="INR",H8,IF(I8="Lakh",H8*100000,IF(I8="Crore",H8*10000000,IF(I8="Thousand",H8*1000,"")))) -> 7774000 | R8: =IF(G8="sqft",F8,IF(G8="sqyd",F8*9,IF(G8="acre",F8*43560,IF(G8="guntha",F8*1089,IF(G8="hectare",F8*107639.1,""))))) -> 1675 | S8: =IF(AND(P8="Resale",R8>0),Q8/R8,"") -> 4641.194 | U8: Kashele | V8: Villa | W8: =COUNTIFS($M$2:$M$209,U8,$N$2:$N$209,V8,$P$2:$P$209,"Resale") -> 13 | X8: {=IFERROR(MEDIAN(_xlfn._xlws.FILTER($S$2:$S$209,($M$2:$M$209=U8)*($N$2:$N$209=V8)*($P$2:$P$209="Resale")*($S$2:$S$209<>""))),"")} -> 3679.2141 | Y8: =IF(AND(P8="Long Term Rental",R8>0),Q8/R8,"") | Z8: =COUNTIFS($M$2:$M$209,U8,$N$2:$N$209,V8,$P$2:$P$209,"Long Term Rental") -> 9 | AA8: {=IF(Z8=0,"",MEDIAN(_xlfn._xlws.FILTER($Y$2:$Y$209,($M$2:$M$209=U8)*($N$2:$N$209=V8)*($P$2:$P$209="Long Term Rental")*($Y$2:$Y$209<>""),"")))} -> 12.094862 | AB8: =IF(AND(V8="Villa",X8<>"",AA8<>""),(AA8*12/X8)*100,"") -> 3.944819 | AC8: {=IFERROR(MEDIAN(_xlfn._xlws.FILTER($Q$2:$Q$209,($M$2:$M$209=U8)*($P$2:$P$209="Short Term Rental")*($Q$2:$Q$209<>""))),"")} -> 4700
A9: K0008 | B9: Farm Land for sale in Karjat Town | C9: Karjat Town | D9: Farm Land | E9: NA | F9: 0.71 | G9: acre | H9: 51.74 | I9: Lakh | J9: One-time | K9: Active | M9: =_xlfn.XLOOKUP(TRIM(C9),MAPPING!A:A,MAPPING!B:B,"CHECK") -> Karjat Town | N9: =_xlfn.XLOOKUP(D9,MAPPING!G:G,MAPPING!H:H,"CHECK") -> Farmland | O9: =_xlfn.XLOOKUP(E9,MAPPING!J:J,MAPPING!K:K,"CHECK") -> NA | P9: =_xlfn.XLOOKUP(J9,MAPPING!M:M,MAPPING!N:N,"CHECK") -> Resale | Q9: =IF(I9="INR",H9,IF(I9="Lakh",H9*100000,IF(I9="Crore",H9*10000000,IF(I9="Thousand",H9*1000,"")))) -> 5174000 | R9: =IF(G9="sqft",F9,IF(G9="sqyd",F9*9,IF(G9="acre",F9*43560,IF(G9="guntha",F9*1089,IF(G9="hectare",F9*107639.1,""))))) -> 30927.6 | S9: =IF(AND(P9="Resale",R9>0),Q9/R9,"") -> 167.29394 | U9: Kashele | V9: Plot | W9: =COUNTIFS($M$2:$M$209,U9,$N$2:$N$209,V9,$P$2:$P$209,"Resale") -> 9 | X9: {=IFERROR(MEDIAN(_xlfn._xlws.FILTER($S$2:$S$209,($M$2:$M$209=U9)*($N$2:$N$209=V9)*($P$2:$P$209="Resale")*($S$2:$S$209<>""))),"")} -> 796.62616 | Y9: =IF(AND(P9="Long Term Rental",R9>0),Q9/R9,"") | Z9: =COUNTIFS($M$2:$M$209,U9,$N$2:$N$209,V9,$P$2:$P$209,"Long Term Rental") -> 0 | AA9: {=IF(Z9=0,"",MEDIAN(_xlfn._xlws.FILTER($Y$2:$Y$209,($M$2:$M$209=U9)*($N$2:$N$209=V9)*($P$2:$P$209="Long Term Rental")*($Y$2:$Y$209<>""),"")))} | AB9: =IF(AND(V9="Villa",X9<>"",AA9<>""),(AA9*12/X9)*100,"") | AC9: {=IFERROR(MEDIAN(_xlfn._xlws.FILTER($Q$2:$Q$209,($M$2:$M$209=U9)*($P$2:$P$209="Short Term Rental")*($Q$2:$Q$209<>""))),"")} -> 4700
A10: K0009 | B10: Land Parcel for sale in Karjat Town | C10: Karjat Town | D10: Land Parcel | E10: NA | F10: 9.1 | G10: guntha | H10: 91.38 | I10: Lakh | J10: One-time | K10: Active | M10: =_xlfn.XLOOKUP(TRIM(C10),MAPPING!A:A,MAPPING!B:B,"CHECK") -> Karjat Town | N10: =_xlfn.XLOOKUP(D10,MAPPING!G:G,MAPPING!H:H,"CHECK") -> Plot | O10: =_xlfn.XLOOKUP(E10,MAPPING!J:J,MAPPING!K:K,"CHECK") -> NA | P10: =_xlfn.XLOOKUP(J10,MAPPING!M:M,MAPPING!N:N,"CHECK") -> Resale | Q10: =IF(I10="INR",H10,IF(I10="Lakh",H10*100000,IF(I10="Crore",H10*10000000,IF(I10="Thousand",H10*1000,"")))) -> 9138000 | R10: =IF(G10="sqft",F10,IF(G10="sqyd",F10*9,IF(G10="acre",F10*43560,IF(G10="guntha",F10*1089,IF(G10="hectare",F10*107639.1,""))))) -> 9909.9 | S10: =IF(AND(P10="Resale",R10>0),Q10/R10,"") -> 922.10819 | U10: Kashele | V10: Farmland | W10: =COUNTIFS($M$2:$M$209,U10,$N$2:$N$209,V10,$P$2:$P$209,"Resale") -> 5 | X10: {=IFERROR(MEDIAN(_xlfn._xlws.FILTER($S$2:$S$209,($M$2:$M$209=U10)*($N$2:$N$209=V10)*($P$2:$P$209="Resale")*($S$2:$S$209<>""))),"")} -> 126.86675 | Y10: =IF(AND(P10="Long Term Rental",R10>0),Q10/R10,"") | Z10: =COUNTIFS($M$2:$M$209,U10,$N$2:$N$209,V10,$P$2:$P$209,"Long Term Rental") -> 0 | AA10: {=IF(Z10=0,"",MEDIAN(_xlfn._xlws.FILTER($Y$2:$Y$209,($M$2:$M$209=U10)*($N$2:$N$209=V10)*($P$2:$P$209="Long Term Rental")*($Y$2:$Y$209<>""),"")))} | AB10: =IF(AND(V10="Villa",X10<>"",AA10<>""),(AA10*12/X10)*100,"") | AC10: {=IFERROR(MEDIAN(_xlfn._xlws.FILTER($Q$2:$Q$209,($M$2:$M$209=U10)*($P$2:$P$209="Short Term Rental")*($Q$2:$Q$209<>""))),"")} -> 4700
A11: K0010 | B11: 3 BHK Bungalow for sale in Karjat Town | C11: Karjat Town | D11: Bungalow | E11: 3 BHK | F11: 2285 | G11: sqft | H11: 1.16 | I11: Crore | J11: One-time | K11: Price on Request | M11: =_xlfn.XLOOKUP(TRIM(C11),MAPPING!A:A,MAPPING!B:B,"CHECK") -> Karjat Town | N11: =_xlfn.XLOOKUP(D11,MAPPING!G:G,MAPPING!H:H,"CHECK") -> Villa | O11: =_xlfn.XLOOKUP(E11,MAPPING!J:J,MAPPING!K:K,"CHECK") -> 3 BHK | P11: =_xlfn.XLOOKUP(J11,MAPPING!M:M,MAPPING!N:N,"CHECK") -> Resale | Q11: =IF(I11="INR",H11,IF(I11="Lakh",H11*100000,IF(I11="Crore",H11*10000000,IF(I11="Thousand",H11*1000,"")))) -> 11600000 | R11: =IF(G11="sqft",F11,IF(G11="sqyd",F11*9,IF(G11="acre",F11*43560,IF(G11="guntha",F11*1089,IF(G11="hectare",F11*107639.1,""))))) -> 2285 | S11: =IF(AND(P11="Resale",R11>0),Q11/R11,"") -> 5076.5864 | U11: Kondhwal Valley | V11: Villa | W11: =COUNTIFS($M$2:$M$209,U11,$N$2:$N$209,V11,$P$2:$P$209,"Resale") -> 6 | X11: {=IFERROR(MEDIAN(_xlfn._xlws.FILTER($S$2:$S$209,($M$2:$M$209=U11)*($N$2:$N$209=V11)*($P$2:$P$209="Resale")*($S$2:$S$209<>""))),"")} -> 3150.9381 | Y11: =IF(AND(P11="Long Term Rental",R11>0),Q11/R11,"") | Z11: =COUNTIFS($M$2:$M$209,U11,$N$2:$N$209,V11,$P$2:$P$209,"Long Term Rental") -> 9 | AA11: {=IF(Z11=0,"",MEDIAN(_xlfn._xlws.FILTER($Y$2:$Y$209,($M$2:$M$209=U11)*($N$2:$N$209=V11)*($P$2:$P$209="Long Term Rental")*($Y$2:$Y$209<>""),"")))} -> 11.477363 | AB11: =IF(AND(V11="Villa",X11<>"",AA11<>""),(AA11*12/X11)*100,"") -> 4.371027 | AC11: {=IFERROR(MEDIAN(_xlfn._xlws.FILTER($Q$2:$Q$209,($M$2:$M$209=U11)*($P$2:$P$209="Short Term Rental")*($Q$2:$Q$209<>""))),"")} -> 6300
A12: K0011 | B12: Land Parcel for sale in Karjat West | C12: Karjat West | D12: Land Parcel | E12: NA | G12: guntha | H12: 85.96 | I12: Lakh | J12: One-time | K12: Active | M12: =_xlfn.XLOOKUP(TRIM(C12),MAPPING!A:A,MAPPING!B:B,"CHECK") -> Karjat Town | N12: =_xlfn.XLOOKUP(D12,MAPPING!G:G,MAPPING!H:H,"CHECK") -> Plot | O12: =_xlfn.XLOOKUP(E12,MAPPING!J:J,MAPPING!K:K,"CHECK") -> NA | P12: =_xlfn.XLOOKUP(J12,MAPPING!M:M,MAPPING!N:N,"CHECK") -> Resale | Q12: =IF(I12="INR",H12,IF(I12="Lakh",H12*100000,IF(I12="Crore",H12*10000000,IF(I12="Thousand",H12*1000,"")))) -> 8596000 | R12: =IF(G12="sqft",F12,IF(G12="sqyd",F12*9,IF(G12="acre",F12*43560,IF(G12="guntha",F12*1089,IF(G12="hectare",F12*107639.1,""))))) -> 0 | S12: =IF(AND(P12="Resale",R12>0),Q12/R12,"") | U12: Kondhwal Valley | V12: Plot | W12: =COUNTIFS($M$2:$M$209,U12,$N$2:$N$209,V12,$P$2:$P$209,"Resale") -> 8 | X12: {=IFERROR(MEDIAN(_xlfn._xlws.FILTER($S$2:$S$209,($M$2:$M$209=U12)*($N$2:$N$209=V12)*($P$2:$P$209="Resale")*($S$2:$S$209<>""))),"")} -> 767.53507 | Y12: =IF(AND(P12="Long Term Rental",R12>0),Q12/R12,"") | Z12: =COUNTIFS($M$2:$M$209,U12,$N$2:$N$209,V12,$P$2:$P$209,"Long Term Rental") -> 0 | AA12: {=IF(Z12=0,"",MEDIAN(_xlfn._xlws.FILTER($Y$2:$Y$209,($M$2:$M$209=U12)*($N$2:$N$209=V12)*($P$2:$P$209="Long Term Rental")*($Y$2:$Y$209<>""),"")))} | AB12: =IF(AND(V12="Villa",X12<>"",AA12<>""),(AA12*12/X12)*100,"") | AC12: {=IFERROR(MEDIAN(_xlfn._xlws.FILTER($Q$2:$Q$209,($M$2:$M$209=U12)*($P$2:$P$209="Short Term Rental")*($Q$2:$Q$209<>""))),"")} -> 6300
A13: K0012 | B13: 3 BHK Row House for sale in Karjat Station Road | C13: Karjat Station Road | D13: Row House | E13: 3 BHK | F13: 2251 | G13: sqft | H13: 88.17 | I13: Lakh | J13: One-time | K13: Active | M13: =_xlfn.XLOOKUP(TRIM(C13),MAPPING!A:A,MAPPING!B:B,"CHECK") -> Karjat Town | N13: =_xlfn.XLOOKUP(D13,MAPPING!G:G,MAPPING!H:H,"CHECK") -> Villa | O13: =_xlfn.XLOOKUP(E13,MAPPING!J:J,MAPPING!K:K,"CHECK") -> 3 BHK | P13: =_xlfn.XLOOKUP(J13,MAPPING!M:M,MAPPING!N:N,"CHECK") -> Resale | Q13: =IF(I13="INR",H13,IF(I13="Lakh",H13*100000,IF(I13="Crore",H13*10000000,IF(I13="Thousand",H13*1000,"")))) -> 8817000 | R13: =IF(G13="sqft",F13,IF(G13="sqyd",F13*9,IF(G13="acre",F13*43560,IF(G13="guntha",F13*1089,IF(G13="hectare",F13*107639.1,""))))) -> 2251 | S13: =IF(AND(P13="Resale",R13>0),Q13/R13,"") -> 3916.9258 | U13: Kondhwal Valley | V13: Farmland | W13: =COUNTIFS($M$2:$M$209,U13,$N$2:$N$209,V13,$P$2:$P$209,"Resale") -> 5 | X13: {=IFERROR(MEDIAN(_xlfn._xlws.FILTER($S$2:$S$209,($M$2:$M$209=U13)*($N$2:$N$209=V13)*($P$2:$P$209="Resale")*($S$2:$S$209<>""))),"")} -> 123.37368 | Y13: =IF(AND(P13="Long Term Rental",R13>0),Q13/R13,"") | Z13: =COUNTIFS($M$2:$M$209,U13,$N$2:$N$209,V13,$P$2:$P$209,"Long Term Rental") -> 0 | AA13: {=IF(Z13=0,"",MEDIAN(_xlfn._xlws.FILTER($Y$2:$Y$209,($M$2:$M$209=U13)*($N$2:$N$209=V13)*($P$2:$P$209="Long Term Rental")*($Y$2:$Y$209<>""),"")))} | AB13: =IF(AND(V13="Villa",X13<>"",AA13<>""),(AA13*12/X13)*100,"") | AC13: {=IFERROR(MEDIAN(_xlfn._xlws.FILTER($Q$2:$Q$209,($M$2:$M$209=U13)*($P$2:$P$209="Short Term Rental")*($Q$2:$Q$209<>""))),"")} -> 6300
A14: K0013 | B14: Farm Land for sale in Karjat Town | C14: Karjat Town | D14: Farm Land | E14: NA | F14: 7642 | G14: sqft | H14: 10.8 | I14: Lakh | J14: One-time | K14: Active | M14: =_xlfn.XLOOKUP(TRIM(C14),MAPPING!A:A,MAPPING!B:B,"CHECK") -> Karjat Town | N14: =_xlfn.XLOOKUP(D14,MAPPING!G:G,MAPPING!H:H,"CHECK") -> Farmland | O14: =_xlfn.XLOOKUP(E14,MAPPING!J:J,MAPPING!K:K,"CHECK") -> NA | P14: =_xlfn.XLOOKUP(J14,MAPPING!M:M,MAPPING!N:N,"CHECK") -> Resale | Q14: =IF(I14="INR",H14,IF(I14="Lakh",H14*100000,IF(I14="Crore",H14*10000000,IF(I14="Thousand",H14*1000,"")))) -> 1080000 | R14: =IF(G14="sqft",F14,IF(G14="sqyd",F14*9,IF(G14="acre",F14*43560,IF(G14="guntha",F14*1089,IF(G14="hectare",F14*107639.1,""))))) -> 7642 | S14: =IF(AND(P14="Resale",R14>0),Q14/R14,"") -> 141.32426 | U14: Matheran Road | V14: Villa | W14: =COUNTIFS($M$2:$M$209,U14,$N$2:$N$209,V14,$P$2:$P$209,"Resale") -> 10 | X14: {=IFERROR(MEDIAN(_xlfn._xlws.FILTER($S$2:$S$209,($M$2:$M$209=U14)*($N$2:$N$209=V14)*($P$2:$P$209="Resale")*($S$2:$S$209<>""))),"")} -> 5034.6152 | Y14: =IF(AND(P14="Long Term Rental",R14>0),Q14/R14,"") | Z14: =COUNTIFS($M$2:$M$209,U14,$N$2:$N$209,V14,$P$2:$P$209,"Long Term Rental") -> 8 | AA14: {=IF(Z14=0,"",MEDIAN(_xlfn._xlws.FILTER($Y$2:$Y$209,($M$2:$M$209=U14)*($N$2:$N$209=V14)*($P$2:$P$209="Long Term Rental")*($Y$2:$Y$209<>""),"")))} -> 15.937632 | AB14: =IF(AND(V14="Villa",X14<>"",AA14<>""),(AA14*12/X14)*100,"") -> 3.7987328 | AC14: {=IFERROR(MEDIAN(_xlfn._xlws.FILTER($Q$2:$Q$209,($M$2:$M$209=U14)*($P$2:$P$209="Short Term Rental")*($Q$2:$Q$209<>""))),"")} -> 5800
A15: K0014 | B15: 3BHK Villa for sale in Karjat Station Road | C15: Karjat Station Road | D15: Villa | E15: 3BHK | F15: 2521 | G15: sqft | H15: 1.02 | I15: Crore | J15: One-time | K15: Price on Request | M15: =_xlfn.XLOOKUP(TRIM(C15),MAPPING!A:A,MAPPING!B:B,"CHECK") -> Karjat Town | N15: =_xlfn.XLOOKUP(D15,MAPPING!G:G,MAPPING!H:H,"CHECK") -> Villa | O15: =_xlfn.XLOOKUP(E15,MAPPING!J:J,MAPPING!K:K,"CHECK") -> 3 BHK | P15: =_xlfn.XLOOKUP(J15,MAPPING!M:M,MAPPING!N:N,"CHECK") -> Resale | Q15: =IF(I15="INR",H15,IF(I15="Lakh",H15*100000,IF(I15="Crore",H15*10000000,IF(I15="Thousand",H15*1000,"")))) -> 10200000 | R15: =IF(G15="sqft",F15,IF(G15="sqyd",F15*9,IF(G15="acre",F15*43560,IF(G15="guntha",F15*1089,IF(G15="hectare",F15*107639.1,""))))) -> 2521 | S15: =IF(AND(P15="Resale",R15>0),Q15/R15,"") -> 4046.0135 | U15: Matheran Road | V15: Plot | W15: =COUNTIFS($M$2:$M$209,U15,$N$2:$N$209,V15,$P$2:$P$209,"Resale") -> 6 | X15: {=IFERROR(MEDIAN(_xlfn._xlws.FILTER($S$2:$S$209,($M$2:$M$209=U15)*($N$2:$N$209=V15)*($P$2:$P$209="Resale")*($S$2:$S$209<>""))),"")} -> 939.08438 | Y15: =IF(AND(P15="Long Term Rental",R15>0),Q15/R15,"") | Z15: =COUNTIFS($M$2:$M$209,U15,$N$2:$N$209,V15,$P$2:$P$209,"Long Term Rental") -> 0 | AA15: {=IF(Z15=0,"",MEDIAN(_xlfn._xlws.FILTER($Y$2:$Y$209,($M$2:$M$209=U15)*($N$2:$N$209=V15)*($P$2:$P$209="Long Term Rental")*($Y$2:$Y$209<>""),"")))} | AB15: =IF(AND(V15="Villa",X15<>"",AA15<>""),(AA15*12/X15)*100,"") | AC15: {=IFERROR(MEDIAN(_xlfn._xlws.FILTER($Q$2:$Q$209,($M$2:$M$209=U15)*($P$2:$P$209="Short Term Rental")*($Q$2:$Q$209<>""))),"")} -> 5800
A16: K0015 | B16: 2 BHK Villa for sale in Karjat Town | C16: Karjat Town | D16: Villa | E16: 2 BHK | F16: 2403 | G16: sqft | H16: 1.05 | I16: Crore | J16: One-time | K16: Active | M16: =_xlfn.XLOOKUP(TRIM(C16),MAPPING!A:A,MAPPING!B:B,"CHECK") -> Karjat Town | N16: =_xlfn.XLOOKUP(D16,MAPPING!G:G,MAPPING!H:H,"CHECK") -> Villa | O16: =_xlfn.XLOOKUP(E16,MAPPING!J:J,MAPPING!K:K,"CHECK") -> 2 BHK | P16: =_xlfn.XLOOKUP(J16,MAPPING!M:M,MAPPING!N:N,"CHECK") -> Resale | Q16: =IF(I16="INR",H16,IF(I16="Lakh",H16*100000,IF(I16="Crore",H16*10000000,IF(I16="Thousand",H16*1000,"")))) -> 10500000 | R16: =IF(G16="sqft",F16,IF(G16="sqyd",F16*9,IF(G16="acre",F16*43560,IF(G16="guntha",F16*1089,IF(G16="hectare",F16*107639.1,""))))) -> 2403 | S16: =IF(AND(P16="Resale",R16>0),Q16/R16,"") -> 4369.5381 | U16: Matheran Road | V16: Farmland | W16: =COUNTIFS($M$2:$M$209,U16,$N$2:$N$209,V16,$P$2:$P$209,"Resale") -> 10 | X16: {=IFERROR(MEDIAN(_xlfn._xlws.FILTER($S$2:$S$209,($M$2:$M$209=U16)*($N$2:$N$209=V16)*($P$2:$P$209="Resale")*($S$2:$S$209<>""))),"")} -> 167.44766 | Y16: =IF(AND(P16="Long Term Rental",R16>0),Q16/R16,"") | Z16: =COUNTIFS($M$2:$M$209,U16,$N$2:$N$209,V16,$P$2:$P$209,"Long Term Rental") -> 0 | AA16: {=IF(Z16=0,"",MEDIAN(_xlfn._xlws.FILTER($Y$2:$Y$209,($M$2:$M$209=U16)*($N$2:$N$209=V16)*($P$2:$P$209="Long Term Rental")*($Y$2:$Y$209<>""),"")))} | AB16: =IF(AND(V16="Villa",X16<>"",AA16<>""),(AA16*12/X16)*100,"") | AC16: {=IFERROR(MEDIAN(_xlfn._xlws.FILTER($Q$2:$Q$209,($M$2:$M$209=U16)*($P$2:$P$209="Short Term Rental")*($Q$2:$Q$209<>""))),"")} -> 5800
A17: K0016 | B17: NA Plot for sale in Central Karjat | C17: Central Karjat | D17: NA Plot | E17: NA | F17: 0.66 | G17: acre | H17: 2.67 | I17: Crore | J17: One-time | K17: Active | M17: =_xlfn.XLOOKUP(TRIM(C17),MAPPING!A:A,MAPPING!B:B,"CHECK") -> Karjat Town | N17: =_xlfn.XLOOKUP(D17,MAPPING!G:G,MAPPING!H:H,"CHECK") -> Plot | O17: =_xlfn.XLOOKUP(E17,MAPPING!J:J,MAPPING!K:K,"CHECK") -> NA | P17: =_xlfn.XLOOKUP(J17,MAPPING!M:M,MAPPING!N:N,"CHECK") -> Resale | Q17: =IF(I17="INR",H17,IF(I17="Lakh",H17*100000,IF(I17="Crore",H17*10000000,IF(I17="Thousand",H17*1000,"")))) -> 26700000 | R17: =IF(G17="sqft",F17,IF(G17="sqyd",F17*9,IF(G17="acre",F17*43560,IF(G17="guntha",F17*1089,IF(G17="hectare",F17*107639.1,""))))) -> 28749.6 | S17: =IF(AND(P17="Resale",R17>0),Q17/R17,"") -> 928.70857 | W17: =COUNTIFS($M$2:$M$209,U17,$N$2:$N$209,V17,$P$2:$P$209,"Resale") -> 0 | X17: {=IFERROR(MEDIAN(_xlfn._xlws.FILTER($S$2:$S$209,($M$2:$M$209=U17)*($N$2:$N$209=V17)*($P$2:$P$209="Resale")*($S$2:$S$209<>""))),"")} | Y17: =IF(AND(P17="Long Term Rental",R17>0),Q17/R17,"") | Z17: =COUNTIFS($M$2:$M$209,U17,$P$2:$P$209,"Long Term Rental") -> 0 | AA17: {=IF(Z17=0,"",MEDIAN(_xlfn._xlws.FILTER($Y$2:$Y$209,($M$2:$M$209=U17)*($N$2:$N$209=V17)*($P$2:$P$209="Long Term Rental")*($Y$2:$Y$209<>""),"")))} | AB17: =IF(AND(V17="Villa",X17<>"",AA17<>""),(AA17*12/X17)*100,"") | AC17: {=IFERROR(MEDIAN(_xlfn._xlws.FILTER($Q$2:$Q$209,($M$2:$M$209=U17)*($P$2:$P$209="Short Term Rental")*($Q$2:$Q$209<>""))),"")}
A18: K0017 | B18: 3BR Independent House for sale in Karjat West | C18: Karjat West | D18: Independent House | E18: 3BR | F18: 2100 | G18: sqft | H18: 99.08 | I18: Lakh | J18: One-time | K18: Price on Request | M18: =_xlfn.XLOOKUP(TRIM(C18),MAPPING!A:A,MAPPING!B:B,"CHECK") -> Karjat Town | N18: =_xlfn.XLOOKUP(D18,MAPPING!G:G,MAPPING!H:H,"CHECK") -> Villa | O18: =_xlfn.XLOOKUP(E18,MAPPING!J:J,MAPPING!K:K,"CHECK") -> 3 BHK | P18: =_xlfn.XLOOKUP(J18,MAPPING!M:M,MAPPING!N:N,"CHECK") -> Resale | Q18: =IF(I18="INR",H18,IF(I18="Lakh",H18*100000,IF(I18="Crore",H18*10000000,IF(I18="Thousand",H18*1000,"")))) -> 9908000 | R18: =IF(G18="sqft",F18,IF(G18="sqyd",F18*9,IF(G18="acre",F18*43560,IF(G18="guntha",F18*1089,IF(G18="hectare",F18*107639.1,""))))) -> 2100 | S18: =IF(AND(P18="Resale",R18>0),Q18/R18,"") -> 4718.0952 | W18: =COUNTIFS($M$2:$M$209,U18,$N$2:$N$209,V18,$P$2:$P$209,"Resale") -> 0 | X18: {=IFERROR(MEDIAN(_xlfn._xlws.FILTER($S$2:$S$209,($M$2:$M$209=U18)*($N$2:$N$209=V18)*($P$2:$P$209="Resale")*($S$2:$S$209<>""))),"")} | Y18: =IF(AND(P18="Long Term Rental",R18>0),Q18/R18,"") | Z18: =COUNTIFS($M$2:$M$209,U18,$P$2:$P$209,"Long Term Rental") -> 0 | AA18: {=IF(Z18=0,"",MEDIAN(_xlfn._xlws.FILTER($Y$2:$Y$209,($M$2:$M$209=U18)*($N$2:$N$209=V18)*($P$2:$P$209="Long Term Rental")*($Y$2:$Y$209<>""),"")))} | AB18: =IF(AND(V18="Villa",X18<>"",AA18<>""),(AA18*12/X18)*100,"") | AC18: {=IFERROR(MEDIAN(_xlfn._xlws.FILTER($Q$2:$Q$209,($M$2:$M$209=U18)*($P$2:$P$209="Short Term Rental")*($Q$2:$Q$209<>""))),"")}
A19: K0018 | B19: Agricultural Land for sale in Karjat | C19: Karjat | D19: Agricultural Land | E19: NA | F19: 2449 | G19: sqft | H19: 3.3 | I19: Lakh | J19: One-time | K19: Active | M19: =_xlfn.XLOOKUP(TRIM(C19),MAPPING!A:A,MAPPING!B:B,"CHECK") -> Karjat Town | N19: =_xlfn.XLOOKUP(D19,MAPPING!G:G,MAPPING!H:H,"CHECK") -> Farmland | O19: =_xlfn.XLOOKUP(E19,MAPPING!J:J,MAPPING!K:K,"CHECK") -> NA | P19: =_xlfn.XLOOKUP(J19,MAPPING!M:M,MAPPING!N:N,"CHECK") -> Resale | Q19: =IF(I19="INR",H19,IF(I19="Lakh",H19*100000,IF(I19="Crore",H19*10000000,IF(I19="Thousand",H19*1000,"")))) -> 330000 | R19: =IF(G19="sqft",F19,IF(G19="sqyd",F19*9,IF(G19="acre",F19*43560,IF(G19="guntha",F19*1089,IF(G19="hectare",F19*107639.1,""))))) -> 2449 | S19: =IF(AND(P19="Resale",R19>0),Q19/R19,"") -> 134.74888 | W19: =COUNTIFS($M$2:$M$209,U19,$N$2:$N$209,V19,$P$2:$P$209,"Resale") -> 0 | X19: {=IFERROR(MEDIAN(_xlfn._xlws.FILTER($S$2:$S$209,($M$2:$M$209=U19)*($N$2:$N$209=V19)*($P$2:$P$209="Resale")*($S$2:$S$209<>""))),"")} | Y19: =IF(AND(P19="Long Term Rental",R19>0),Q19/R19,"") | Z19: =COUNTIFS($M$2:$M$209,U19,$P$2:$P$209,"Long Term Rental") -> 0 | AA19: {=IF(Z19=0,"",MEDIAN(_xlfn._xlws.FILTER($Y$2:$Y$209,($M$2:$M$209=U19)*($N$2:$N$209=V19)*($P$2:$P$209="Long Term Rental")*($Y$2:$Y$209<>""),"")))} | AB19: =IF(AND(V19="Villa",X19<>"",AA19<>""),(AA19*12/X19)*100,"") | AC19: {=IFERROR(MEDIAN(_xlfn._xlws.FILTER($Q$2:$Q$209,($M$2:$M$209=U19)*($P$2:$P$209="Short Term Rental")*($Q$2:$Q$209<>""))),"")}
A20: K0019 | B20: 3BR Row House for sale in Karjat | C20: Karjat | D20: Row House | E20: 3BR | F20: 1198 | G20: sqft | H20: 56.59 | I20: Lakh | J20: One-time | K20: Active | M20: =_xlfn.XLOOKUP(TRIM(C20),MAPPING!A:A,MAPPING!B:B,"CHECK") -> Karjat Town | N20: =_xlfn.XLOOKUP(D20,MAPPING!G:G,MAPPING!H:H,"CHECK") -> Villa | O20: =_xlfn.XLOOKUP(E20,MAPPING!J:J,MAPPING!K:K,"CHECK") -> 3 BHK | P20: =_xlfn.XLOOKUP(J20,MAPPING!M:M,MAPPING!N:N,"CHECK") -> Resale | Q20: =IF(I20="INR",H20,IF(I20="Lakh",H20*100000,IF(I20="Crore",H20*10000000,IF(I20="Thousand",H20*1000,"")))) -> 5659000 | R20: =IF(G20="sqft",F20,IF(G20="sqyd",F20*9,IF(G20="acre",F20*43560,IF(G20="guntha",F20*1089,IF(G20="hectare",F20*107639.1,""))))) -> 1198 | S20: =IF(AND(P20="Resale",R20>0),Q20/R20,"") -> 4723.7062 | W20: =COUNTIFS($M$2:$M$209,U20,$N$2:$N$209,V20,$P$2:$P$209,"Resale") -> 0 | X20: {=IFERROR(MEDIAN(_xlfn._xlws.FILTER($S$2:$S$209,($M$2:$M$209=U20)*($N$2:$N$209=V20)*($P$2:$P$209="Resale")*($S$2:$S$209<>""))),"")} | Y20: =IF(AND(P20="Long Term Rental",R20>0),Q20/R20,"") | Z20: =COUNTIFS($M$2:$M$209,U20,$P$2:$P$209,"Long Term Rental") -> 0 | AA20: {=IF(Z20=0,"",MEDIAN(_xlfn._xlws.FILTER($Y$2:$Y$209,($M$2:$M$209=U20)*($N$2:$N$209=V20)*($P$2:$P$209="Long Term Rental")*($Y$2:$Y$209<>""),"")))} | AB20: =IF(AND(V20="Villa",X20<>"",AA20<>""),(AA20*12/X20)*100,"") | AC20: {=IFERROR(MEDIAN(_xlfn._xlws.FILTER($Q$2:$Q$209,($M$2:$M$209=U20)*($P$2:$P$209="Short Term Rental")*($Q$2:$Q$209<>""))),"")}
A21: K0020 | B21: Farm Land for sale in Central Karjat | C21: Central Karjat | D21: Farm Land | E21: NA | F21: 5974 | G21: sqft | H21: 9.61 | I21: Lakh | J21: One-time | K21: Active | M21: =_xlfn.XLOOKUP(TRIM(C21),MAPPING!A:A,MAPPING!B:B,"CHECK") -> Karjat Town | N21: =_xlfn.XLOOKUP(D21,MAPPING!G:G,MAPPING!H:H,"CHECK") -> Farmland | O21: =_xlfn.XLOOKUP(E21,MAPPING!J:J,MAPPING!K:K,"CHECK") -> NA | P21: =_xlfn.XLOOKUP(J21,MAPPING!M:M,MAPPING!N:N,"CHECK") -> Resale | Q21: =IF(I21="INR",H21,IF(I21="Lakh",H21*100000,IF(I21="Crore",H21*10000000,IF(I21="Thousand",H21*1000,"")))) -> 961000 | R21: =IF(G21="sqft",F21,IF(G21="sqyd",F21*9,IF(G21="acre",F21*43560,IF(G21="guntha",F21*1089,IF(G21="hectare",F21*107639.1,""))))) -> 5974 | S21: =IF(AND(P21="Resale",R21>0),Q21/R21,"") -> 160.86374 | W21: =COUNTIFS($M$2:$M$209,U21,$N$2:$N$209,V21,$P$2:$P$209,"Resale") -> 0 | X21: {=IFERROR(MEDIAN(_xlfn._xlws.FILTER($S$2:$S$209,($M$2:$M$209=U21)*($N$2:$N$209=V21)*($P$2:$P$209="Resale")*($S$2:$S$209<>""))),"")} | Y21: =IF(AND(P21="Long Term Rental",R21>0),Q21/R21,"") | Z21: =COUNTIFS($M$2:$M$209,U21,$P$2:$P$209,"Long Term Rental") -> 0 | AA21: {=IF(Z21=0,"",MEDIAN(_xlfn._xlws.FILTER($Y$2:$Y$209,($M$2:$M$209=U21)*($N$2:$N$209=V21)*($P$2:$P$209="Long Term Rental")*($Y$2:$Y$209<>""),"")))} | AB21: =IF(AND(V21="Villa",X21<>"",AA21<>""),(AA21*12/X21)*100,"") | AC21: {=IFERROR(MEDIAN(_xlfn._xlws.FILTER($Q$2:$Q$209,($M$2:$M$209=U21)*($P$2:$P$209="Short Term Rental")*($Q$2:$Q$209<>""))),"")}
A22: K0021 | B22: 3BR Row House for sale in Central Karjat | C22: Central Karjat | D22: Row House | E22: 3BR | F22: 3049 | G22: sqft | H22: 1.28 | I22: Crore | J22: One-time | K22: Sold | M22: =_xlfn.XLOOKUP(TRIM(C22),MAPPING!A:A,MAPPING!B:B,"CHECK") -> Karjat Town | N22: =_xlfn.XLOOKUP(D22,MAPPING!G:G,MAPPING!H:H,"CHECK") -> Villa | O22: =_xlfn.XLOOKUP(E22,MAPPING!J:J,MAPPING!K:K,"CHECK") -> 3 BHK | P22: =_xlfn.XLOOKUP(J22,MAPPING!M:M,MAPPING!N:N,"CHECK") -> Resale | Q22: =IF(I22="INR",H22,IF(I22="Lakh",H22*100000,IF(I22="Crore",H22*10000000,IF(I22="Thousand",H22*1000,"")))) -> 12800000 | R22: =IF(G22="sqft",F22,IF(G22="sqyd",F22*9,IF(G22="acre",F22*43560,IF(G22="guntha",F22*1089,IF(G22="hectare",F22*107639.1,""))))) -> 3049 | S22: =IF(AND(P22="Resale",R22>0),Q22/R22,"") -> 4198.0977 | W22: =COUNTIFS($M$2:$M$209,U22,$N$2:$N$209,V22,$P$2:$P$209,"Resale") -> 0 | X22: {=IFERROR(MEDIAN(_xlfn._xlws.FILTER($S$2:$S$209,($M$2:$M$209=U22)*($N$2:$N$209=V22)*($P$2:$P$209="Resale")*($S$2:$S$209<>""))),"")} | Y22: =IF(AND(P22="Long Term Rental",R22>0),Q22/R22,"") | Z22: =COUNTIFS($M$2:$M$209,U22,$P$2:$P$209,"Long Term Rental") -> 0 | AA22: {=IF(Z22=0,"",MEDIAN(_xlfn._xlws.FILTER($Y$2:$Y$209,($M$2:$M$209=U22)*($N$2:$N$209=V22)*($P$2:$P$209="Long Term Rental")*($Y$2:$Y$209<>""),"")))} | AB22: =IF(AND(V22="Villa",X22<>"",AA22<>""),(AA22*12/X22)*100,"") | AC22: {=IFERROR(MEDIAN(_xlfn._xlws.FILTER($Q$2:$Q$209,($M$2:$M$209=U22)*($P$2:$P$209="Short Term Rental")*($Q$2:$Q$209<>""))),"")}
A23: K0022 | B23: Plot for sale in Karjat West | C23: Karjat West | D23: Plot | E23: NA | F23: 5.8 | G23: guntha | H23: 61.5 | I23: Lakh | J23: One-time | K23: Active | M23: =_xlfn.XLOOKUP(TRIM(C23),MAPPING!A:A,MAPPING!B:B,"CHECK") -> Karjat Town | N23: =_xlfn.XLOOKUP(D23,MAPPING!G:G,MAPPING!H:H,"CHECK") -> Plot | O23: =_xlfn.XLOOKUP(E23,MAPPING!J:J,MAPPING!K:K,"CHECK") -> NA | P23: =_xlfn.XLOOKUP(J23,MAPPING!M:M,MAPPING!N:N,"CHECK") -> Resale | Q23: =IF(I23="INR",H23,IF(I23="Lakh",H23*100000,IF(I23="Crore",H23*10000000,IF(I23="Thousand",H23*1000,"")))) -> 6150000 | R23: =IF(G23="sqft",F23,IF(G23="sqyd",F23*9,IF(G23="acre",F23*43560,IF(G23="guntha",F23*1089,IF(G23="hectare",F23*107639.1,""))))) -> 6316.2 | S23: =IF(AND(P23="Resale",R23>0),Q23/R23,"") -> 973.68671 | W23: =COUNTIFS($M$2:$M$209,U23,$N$2:$N$209,V23,$P$2:$P$209,"Resale") -> 0 | X23: {=IFERROR(MEDIAN(_xlfn._xlws.FILTER($S$2:$S$209,($M$2:$M$209=U23)*($N$2:$N$209=V23)*($P$2:$P$209="Resale")*($S$2:$S$209<>""))),"")} | Y23: =IF(AND(P23="Long Term Rental",R23>0),Q23/R23,"") | Z23: =COUNTIFS($M$2:$M$209,U23,$P$2:$P$209,"Long Term Rental") -> 0 | AA23: {=IF(Z23=0,"",MEDIAN(_xlfn._xlws.FILTER($Y$2:$Y$209,($M$2:$M$209=U23)*($N$2:$N$209=V23)*($P$2:$P$209="Long Term Rental")*($Y$2:$Y$209<>""),"")))} | AB23: =IF(AND(V23="Villa",X23<>"",AA23<>""),(AA23*12/X23)*100,"") | AC23: {=IFERROR(MEDIAN(_xlfn._xlws.FILTER($Q$2:$Q$209,($M$2:$M$209=U23)*($P$2:$P$209="Short Term Rental")*($Q$2:$Q$209<>""))),"")}
A24: K0023 | B24: 2 BHK Row House for sale in Karjat West | C24: Karjat West | D24: Row House | E24: 2 BHK | F24: 1366 | G24: sqft | H24: 63.46 | I24: Lakh | J24: One-time | K24: Active | M24: =_xlfn.XLOOKUP(TRIM(C24),MAPPING!A:A,MAPPING!B:B,"CHECK") -> Karjat Town | N24: =_xlfn.XLOOKUP(D24,MAPPING!G:G,MAPPING!H:H,"CHECK") -> Villa | O24: =_xlfn.XLOOKUP(E24,MAPPING!J:J,MAPPING!K:K,"CHECK") -> 2 BHK | P24: =_xlfn.XLOOKUP(J24,MAPPING!M:M,MAPPING!N:N,"CHECK") -> Resale | Q24: =IF(I24="INR",H24,IF(I24="Lakh",H24*100000,IF(I24="Crore",H24*10000000,IF(I24="Thousand",H24*1000,"")))) -> 6346000 | R24: =IF(G24="sqft",F24,IF(G24="sqyd",F24*9,IF(G24="acre",F24*43560,IF(G24="guntha",F24*1089,IF(G24="hectare",F24*107639.1,""))))) -> 1366 | S24: =IF(AND(P24="Resale",R24>0),Q24/R24,"") -> 4645.6808 | W24: =COUNTIFS($M$2:$M$209,U24,$N$2:$N$209,V24,$P$2:$P$209,"Resale") -> 0 | X24: {=IFERROR(MEDIAN(_xlfn._xlws.FILTER($S$2:$S$209,($M$2:$M$209=U24)*($N$2:$N$209=V24)*($P$2:$P$209="Resale")*($S$2:$S$209<>""))),"")} | Y24: =IF(AND(P24="Long Term Rental",R24>0),Q24/R24,"") | Z24: =COUNTIFS($M$2:$M$209,U24,$P$2:$P$209,"Long Term Rental") -> 0 | AA24: {=IF(Z24=0,"",MEDIAN(_xlfn._xlws.FILTER($Y$2:$Y$209,($M$2:$M$209=U24)*($N$2:$N$209=V24)*($P$2:$P$209="Long Term Rental")*($Y$2:$Y$209<>""),"")))} | AB24: =IF(AND(V24="Villa",X24<>"",AA24<>""),(AA24*12/X24)*100,"") | AC24: {=IFERROR(MEDIAN(_xlfn._xlws.FILTER($Q$2:$Q$209,($M$2:$M$209=U24)*($P$2:$P$209="Short Term Rental")*($Q$2:$Q$209<>""))),"")}
A25: K0024 | B25: NA Plot for sale in Central Karjat | C25: Central Karjat | D25: NA Plot | E25: NA | F25: 2.72 | G25: acre | H25: 11.75 | I25: Crore | J25: One-time | K25: Active | M25: =_xlfn.XLOOKUP(TRIM(C25),MAPPING!A:A,MAPPING!B:B,"CHECK") -> Karjat Town | N25: =_xlfn.XLOOKUP(D25,MAPPING!G:G,MAPPING!H:H,"CHECK") -> Plot | O25: =_xlfn.XLOOKUP(E25,MAPPING!J:J,MAPPING!K:K,"CHECK") -> NA | P25: =_xlfn.XLOOKUP(J25,MAPPING!M:M,MAPPING!N:N,"CHECK") -> Resale | Q25: =IF(I25="INR",H25,IF(I25="Lakh",H25*100000,IF(I25="Crore",H25*10000000,IF(I25="Thousand",H25*1000,"")))) -> 117500000 | R25: =IF(G25="sqft",F25,IF(G25="sqyd",F25*9,IF(G25="acre",F25*43560,IF(G25="guntha",F25*1089,IF(G25="hectare",F25*107639.1,""))))) -> 118483.2 | S25: =IF(AND(P25="Resale",R25>0),Q25/R25,"") -> 991.70178 | W25: =COUNTIFS($M$2:$M$209,U25,$N$2:$N$209,V25,$P$2:$P$209,"Resale") -> 0 | X25: {=IFERROR(MEDIAN(_xlfn._xlws.FILTER($S$2:$S$209,($M$2:$M$209=U25)*($N$2:$N$209=V25)*($P$2:$P$209="Resale")*($S$2:$S$209<>""))),"")} | Y25: =IF(AND(P25="Long Term Rental",R25>0),Q25/R25,"") | Z25: =COUNTIFS($M$2:$M$209,U25,$P$2:$P$209,"Long Term Rental") -> 0 | AA25: {=IF(Z25=0,"",MEDIAN(_xlfn._xlws.FILTER($Y$2:$Y$209,($M$2:$M$209=U25)*($N$2:$N$209=V25)*($P$2:$P$209="Long Term Rental")*($Y$2:$Y$209<>""),"")))} | AB25: =IF(AND(V25="Villa",X25<>"",AA25<>""),(AA25*12/X25)*100,"") | AC25: {=IFERROR(MEDIAN(_xlfn._xlws.FILTER($Q$2:$Q$209,($M$2:$M$209=U25)*($P$2:$P$209="Short Term Rental")*($Q$2:$Q$209<>""))),"")}
A26: K0025 | B26: 2 BHK Bungalow for rent in Karjat Town | C26: Karjat Town | D26: Bungalow | E26: 2 BHK | F26: 1794 | G26: sqft | H26: 28100 | I26: INR | J26: Monthly | K26: Active | M26: =_xlfn.XLOOKUP(TRIM(C26),MAPPING!A:A,MAPPING!B:B,"CHECK") -> Karjat Town | N26: =_xlfn.XLOOKUP(D26,MAPPING!G:G,MAPPING!H:H,"CHECK") -> Villa | O26: =_xlfn.XLOOKUP(E26,MAPPING!J:J,MAPPING!K:K,"CHECK") -> 2 BHK | P26: =_xlfn.XLOOKUP(J26,MAPPING!M:M,MAPPING!N:N,"CHECK") -> Long Term Rental | Q26: =IF(I26="INR",H26,IF(I26="Lakh",H26*100000,IF(I26="Crore",H26*10000000,IF(I26="Thousand",H26*1000,"")))) -> 28100 | R26: =IF(G26="sqft",F26,IF(G26="sqyd",F26*9,IF(G26="acre",F26*43560,IF(G26="guntha",F26*1089,IF(G26="hectare",F26*107639.1,""))))) -> 1794 | S26: =IF(AND(P26="Resale",R26>0),Q26/R26,"") | W26: =COUNTIFS($M$2:$M$209,U26,$N$2:$N$209,V26,$P$2:$P$209,"Resale") -> 0 | X26: {=IFERROR(MEDIAN(_xlfn._xlws.FILTER($S$2:$S$209,($M$2:$M$209=U26)*($N$2:$N$209=V26)*($P$2:$P$209="Resale")*($S$2:$S$209<>""))),"")} | Y26: =IF(AND(P26="Long Term Rental",R26>0),Q26/R26,"") -> 15.663322 | Z26: =COUNTIFS($M$2:$M$209,U26,$P$2:$P$209,"Long Term Rental") -> 0 | AA26: {=IF(Z26=0,"",MEDIAN(_xlfn._xlws.FILTER($Y$2:$Y$209,($M$2:$M$209=U26)*($N$2:$N$209=V26)*($P$2:$P$209="Long Term Rental")*($Y$2:$Y$209<>""),"")))} | AB26: =IF(AND(V26="Villa",X26<>"",AA26<>""),(AA26*12/X26)*100,"") | AC26: {=IFERROR(MEDIAN(_xlfn._xlws.FILTER($Q$2:$Q$209,($M$2:$M$209=U26)*($P$2:$P$209="Short Term Rental")*($Q$2:$Q$209<>""))),"")}
A27: K0026 | B27: 3 BHK Villa for rent in Central Karjat | C27: Central Karjat | D27: Villa | E27: 3 BHK | F27: 1440 | G27: sqft | H27: 20000 | I27: INR | J27: Monthly | K27: Active | M27: =_xlfn.XLOOKUP(TRIM(C27),MAPPING!A:A,MAPPING!B:B,"CHECK") -> Karjat Town | N27: =_xlfn.XLOOKUP(D27,MAPPING!G:G,MAPPING!H:H,"CHECK") -> Villa | O27: =_xlfn.XLOOKUP(E27,MAPPING!J:J,MAPPING!K:K,"CHECK") -> 3 BHK | P27: =_xlfn.XLOOKUP(J27,MAPPING!M:M,MAPPING!N:N,"CHECK") -> Long Term Rental | Q27: =IF(I27="INR",H27,IF(I27="Lakh",H27*100000,IF(I27="Crore",H27*10000000,IF(I27="Thousand",H27*1000,"")))) -> 20000 | R27: =IF(G27="sqft",F27,IF(G27="sqyd",F27*9,IF(G27="acre",F27*43560,IF(G27="guntha",F27*1089,IF(G27="hectare",F27*107639.1,""))))) -> 1440 | S27: =IF(AND(P27="Resale",R27>0),Q27/R27,"") | W27: =COUNTIFS($M$2:$M$209,U27,$N$2:$N$209,V27,$P$2:$P$209,"Resale") -> 0 | X27: {=IFERROR(MEDIAN(_xlfn._xlws.FILTER($S$2:$S$209,($M$2:$M$209=U27)*($N$2:$N$209=V27)*($P$2:$P$209="Resale")*($S$2:$S$209<>""))),"")} | Y27: =IF(AND(P27="Long Term Rental",R27>0),Q27/R27,"") -> 13.888889 | Z27: =COUNTIFS($M$2:$M$209,U27,$P$2:$P$209,"Long Term Rental") -> 0 | AA27: {=IF(Z27=0,"",MEDIAN(_xlfn._xlws.FILTER($Y$2:$Y$209,($M$2:$M$209=U27)*($N$2:$N$209=V27)*($P$2:$P$209="Long Term Rental")*($Y$2:$Y$209<>""),"")))} | AB27: =IF(AND(V27="Villa",X27<>"",AA27<>""),(AA27*12/X27)*100,"") | AC27: {=IFERROR(MEDIAN(_xlfn._xlws.FILTER($Q$2:$Q$209,($M$2:$M$209=U27)*($P$2:$P$209="Short Term Rental")*($Q$2:$Q$209<>""))),"")}
A28: K0027 | B28: 3 BHK Row House for rent in Karjat Station Road | C28: Karjat Station Road | D28: Row House | E28: 3 BHK | F28: 1513 | G28: sqft | H28: 23700 | I28: INR | J28: Monthly | K28: Active | M28: =_xlfn.XLOOKUP(TRIM(C28),MAPPING!A:A,MAPPING!B:B,"CHECK") -> Karjat Town | N28: =_xlfn.XLOOKUP(D28,MAPPING!G:G,MAPPING!H:H,"CHECK") -> Villa | O28: =_xlfn.XLOOKUP(E28,MAPPING!J:J,MAPPING!K:K,"CHECK") -> 3 BHK | P28: =_xlfn.XLOOKUP(J28,MAPPING!M:M,MAPPING!N:N,"CHECK") -> Long Term Rental | Q28: =IF(I28="INR",H28,IF(I28="Lakh",H28*100000,IF(I28="Crore",H28*10000000,IF(I28="Thousand",H28*1000,"")))) -> 23700 | R28: =IF(G28="sqft",F28,IF(G28="sqyd",F28*9,IF(G28="acre",F28*43560,IF(G28="guntha",F28*1089,IF(G28="hectare",F28*107639.1,""))))) -> 1513 | S28: =IF(AND(P28="Resale",R28>0),Q28/R28,"") | W28: =COUNTIFS($M$2:$M$209,U28,$N$2:$N$209,V28,$P$2:$P$209,"Resale") -> 0 | X28: {=IFERROR(MEDIAN(_xlfn._xlws.FILTER($S$2:$S$209,($M$2:$M$209=U28)*($N$2:$N$209=V28)*($P$2:$P$209="Resale")*($S$2:$S$209<>""))),"")} | Y28: =IF(AND(P28="Long Term Rental",R28>0),Q28/R28,"") -> 15.664243 | Z28: =COUNTIFS($M$2:$M$209,U28,$P$2:$P$209,"Long Term Rental") -> 0 | AA28: {=IF(Z28=0,"",MEDIAN(_xlfn._xlws.FILTER($Y$2:$Y$209,($M$2:$M$209=U28)*($N$2:$N$209=V28)*($P$2:$P$209="Long Term Rental")*($Y$2:$Y$209<>""),"")))} | AB28: =IF(AND(V28="Villa",X28<>"",AA28<>""),(AA28*12/X28)*100,"") | AC28: {=IFERROR(MEDIAN(_xlfn._xlws.FILTER($Q$2:$Q$209,($M$2:$M$209=U28)*($P$2:$P$209="Short Term Rental")*($Q$2:$Q$209<>""))),"")}
... A34: K0033 | B34: 3BR Villa for rent in Central Karjat | C34: Central Karjat | D34: Villa | E34: 3BR | F34: 1621 | G34: sqft | H34: 23600 | I34: INR | J34: Monthly | K34: Active | M34: =_xlfn.XLOOKUP(TRIM(C34),MAPPING!A:A,MAPPING!B:B,"CHECK") -> Karjat Town | N34: =_xlfn.XLOOKUP(D34,MAPPING!G:G,MAPPING!H:H,"CHECK") -> Villa | O34: =_xlfn.XLOOKUP(E34,MAPPING!J:J,MAPPING!K:K,"CHECK") -> 3 BHK | P34: =_xlfn.XLOOKUP(J34,MAPPING!M:M,MAPPING!N:N,"CHECK") -> Long Term Rental | Q34: =IF(I34="INR",H34,IF(I34="Lakh",H34*100000,IF(I34="Crore",H34*10000000,IF(I34="Thousand",H34*1000,"")))) -> 23600 | R34: =IF(G34="sqft",F34,IF(G34="sqyd",F34*9,IF(G34="acre",F34*43560,IF(G34="guntha",F34*1089,IF(G34="hectare",F34*107639.1,""))))) -> 1621 | S34: =IF(AND(P34="Resale",R34>0),Q34/R34,"") | W34: =COUNTIFS($M$2:$M$209,U34,$N$2:$N$209,V34,$P$2:$P$209,"Resale") -> 0 | X34: {=IFERROR(MEDIAN(_xlfn._xlws.FILTER($S$2:$S$209,($M$2:$M$209=U34)*($N$2:$N$209=V34)*($P$2:$P$209="Resale")*($S$2:$S$209<>""))),"")} | Y34: =IF(AND(P34="Long Term Rental",R34>0),Q34/R34,"") -> 14.558914 | Z34: =COUNTIFS($M$2:$M$209,U34,$P$2:$P$209,"Long Term Rental") -> 0 | AA34: {=IF(Z34=0,"",MEDIAN(_xlfn._xlws.FILTER($Y$2:$Y$209,($M$2:$M$209=U34)*($N$2:$N$209=V34)*($P$2:$P$209="Long Term Rental")*($Y$2:$Y$209<>""),"")))} | AB34: =IF(AND(V34="Villa",X34<>"",AA34<>""),(AA34*12/X34)*100,"") | AC34: {=IFERROR(MEDIAN(_xlfn._xlws.FILTER($Q$2:$Q$209,($M$2:$M$209=U34)*($P$2:$P$209="Short Term Rental")*($Q$2:$Q$209<>""))),"")}
A35: K0034 | B35: 3BR Bungalow for weekend stay near Karjat Station Road | C35: Karjat Station Road | D35: Bungalow | E35: 3BR | H35: 8300 | I35: INR | J35: Per Night | K35: Active | L35: Forward 60-day availability calendar; not a confirmed-stay record. | M35: =_xlfn.XLOOKUP(TRIM(C35),MAPPING!A:A,MAPPING!B:B,"CHECK") -> Karjat Town | N35: =_xlfn.XLOOKUP(D35,MAPPING!G:G,MAPPING!H:H,"CHECK") -> Villa | O35: =_xlfn.XLOOKUP(E35,MAPPING!J:J,MAPPING!K:K,"CHECK") -> 3 BHK | P35: =_xlfn.XLOOKUP(J35,MAPPING!M:M,MAPPING!N:N,"CHECK") -> Short Term Rental | Q35: =IF(I35="INR",H35,IF(I35="Lakh",H35*100000,IF(I35="Crore",H35*10000000,IF(I35="Thousand",H35*1000,"")))) -> 8300 | R35: =IF(G35="sqft",F35,IF(G35="sqyd",F35*9,IF(G35="acre",F35*43560,IF(G35="guntha",F35*1089,IF(G35="hectare",F35*107639.1,""))))) | S35: =IF(AND(P35="Resale",R35>0),Q35/R35,"") | W35: =COUNTIFS($M$2:$M$209,U35,$N$2:$N$209,V35,$P$2:$P$209,"Resale") -> 0 | X35: {=IFERROR(MEDIAN(_xlfn._xlws.FILTER($S$2:$S$209,($M$2:$M$209=U35)*($N$2:$N$209=V35)*($P$2:$P$209="Resale")*($S$2:$S$209<>""))),"")} | Y35: =IF(AND(P35="Long Term Rental",R35>0),Q35/R35,"") | Z35: =COUNTIFS($M$2:$M$209,U35,$P$2:$P$209,"Long Term Rental") -> 0 | AA35: {=IF(Z35=0,"",MEDIAN(_xlfn._xlws.FILTER($Y$2:$Y$209,($M$2:$M$209=U35)*($N$2:$N$209=V35)*($P$2:$P$209="Long Term Rental")*($Y$2:$Y$209<>""),"")))} | AB35: =IF(AND(V35="Villa",X35<>"",AA35<>""),(AA35*12/X35)*100,"") | AC35: {=IFERROR(MEDIAN(_xlfn._xlws.FILTER($Q$2:$Q$209,($M$2:$M$209=U35)*($P$2:$P$209="Short Term Rental")*($Q$2:$Q$209<>""))),"")}
A36: K0035 | B36: 2BHK Bungalow for weekend stay near Karjat Town | C36: Karjat Town | D36: Bungalow | E36: 2BHK | H36: 7500 | I36: INR | J36: Per Night | K36: Active | L36: Forward 60-day availability calendar; not a confirmed-stay record. | M36: =_xlfn.XLOOKUP(TRIM(C36),MAPPING!A:A,MAPPING!B:B,"CHECK") -> Karjat Town | N36: =_xlfn.XLOOKUP(D36,MAPPING!G:G,MAPPING!H:H,"CHECK") -> Villa | O36: =_xlfn.XLOOKUP(E36,MAPPING!J:J,MAPPING!K:K,"CHECK") -> 2 BHK | P36: =_xlfn.XLOOKUP(J36,MAPPING!M:M,MAPPING!N:N,"CHECK") -> Short Term Rental | Q36: =IF(I36="INR",H36,IF(I36="Lakh",H36*100000,IF(I36="Crore",H36*10000000,IF(I36="Thousand",H36*1000,"")))) -> 7500 | R36: =IF(G36="sqft",F36,IF(G36="sqyd",F36*9,IF(G36="acre",F36*43560,IF(G36="guntha",F36*1089,IF(G36="hectare",F36*107639.1,""))))) | S36: =IF(AND(P36="Resale",R36>0),Q36/R36,"") | W36: =COUNTIFS($M$2:$M$209,U36,$N$2:$N$209,V36,$P$2:$P$209,"Resale") -> 0 | X36: {=IFERROR(MEDIAN(_xlfn._xlws.FILTER($S$2:$S$209,($M$2:$M$209=U36)*($N$2:$N$209=V36)*($P$2:$P$209="Resale")*($S$2:$S$209<>""))),"")} | Y36: =IF(AND(P36="Long Term Rental",R36>0),Q36/R36,"") | Z36: =COUNTIFS($M$2:$M$209,U36,$P$2:$P$209,"Long Term Rental") -> 0 | AA36: {=IF(Z36=0,"",MEDIAN(_xlfn._xlws.FILTER($Y$2:$Y$209,($M$2:$M$209=U36)*($N$2:$N$209=V36)*($P$2:$P$209="Long Term Rental")*($Y$2:$Y$209<>""),"")))} | AB36: =IF(AND(V36="Villa",X36<>"",AA36<>""),(AA36*12/X36)*100,"") | AC36: {=IFERROR(MEDIAN(_xlfn._xlws.FILTER($Q$2:$Q$209,($M$2:$M$209=U36)*($P$2:$P$209="Short Term Rental")*($Q$2:$Q$209<>""))),"")}
A37: K0036 | B37: 3 BHK Villa for weekend stay near Karjat Town | C37: Karjat Town | D37: Villa | E37: 3 BHK | H37: 8900 | I37: INR | J37: Per Night | K37: Active | L37: Forward 60-day availability calendar; not a confirmed-stay record. | M37: =_xlfn.XLOOKUP(TRIM(C37),MAPPING!A:A,MAPPING!B:B,"CHECK") -> Karjat Town | N37: =_xlfn.XLOOKUP(D37,MAPPING!G:G,MAPPING!H:H,"CHECK") -> Villa | O37: =_xlfn.XLOOKUP(E37,MAPPING!J:J,MAPPING!K:K,"CHECK") -> 3 BHK | P37: =_xlfn.XLOOKUP(J37,MAPPING!M:M,MAPPING!N:N,"CHECK") -> Short Term Rental | Q37: =IF(I37="INR",H37,IF(I37="Lakh",H37*100000,IF(I37="Crore",H37*10000000,IF(I37="Thousand",H37*1000,"")))) -> 8900 | R37: =IF(G37="sqft",F37,IF(G37="sqyd",F37*9,IF(G37="acre",F37*43560,IF(G37="guntha",F37*1089,IF(G37="hectare",F37*107639.1,""))))) | S37: =IF(AND(P37="Resale",R37>0),Q37/R37,"") | W37: =COUNTIFS($M$2:$M$209,U37,$N$2:$N$209,V37,$P$2:$P$209,"Resale") -> 0 | X37: {=IFERROR(MEDIAN(_xlfn._xlws.FILTER($S$2:$S$209,($M$2:$M$209=U37)*($N$2:$N$209=V37)*($P$2:$P$209="Resale")*($S$2:$S$209<>""))),"")} | Y37: =IF(AND(P37="Long Term Rental",R37>0),Q37/R37,"") | Z37: =COUNTIFS($M$2:$M$209,U37,$P$2:$P$209,"Long Term Rental") -> 0 | AA37: {=IF(Z37=0,"",MEDIAN(_xlfn._xlws.FILTER($Y$2:$Y$209,($M$2:$M$209=U37)*($N$2:$N$209=V37)*($P$2:$P$209="Long Term Rental")*($Y$2:$Y$209<>""),"")))} | AB37: =IF(AND(V37="Villa",X37<>"",AA37<>""),(AA37*12/X37)*100,"") | AC37: {=IFERROR(MEDIAN(_xlfn._xlws.FILTER($Q$2:$Q$209,($M$2:$M$209=U37)*($P$2:$P$209="Short Term Rental")*($Q$2:$Q$209<>""))),"")}
A38: K0037 | B38: 3BHK Farmhouse for weekend stay near Karjat | C38: Karjat | D38: Farmhouse | E38: 3BHK | H38: 6300 | I38: INR | J38: Per Night | K38: Active | L38: Forward 60-day availability calendar; not a confirmed-stay record. | M38: =_xlfn.XLOOKUP(TRIM(C38),MAPPING!A:A,MAPPING!B:B,"CHECK") -> Karjat Town | N38: =_xlfn.XLOOKUP(D38,MAPPING!G:G,MAPPING!H:H,"CHECK") -> Villa | O38: =_xlfn.XLOOKUP(E38,MAPPING!J:J,MAPPING!K:K,"CHECK") -> 3 BHK | P38: =_xlfn.XLOOKUP(J38,MAPPING!M:M,MAPPING!N:N,"CHECK") -> Short Term Rental | Q38: =IF(I38="INR",H38,IF(I38="Lakh",H38*100000,IF(I38="Crore",H38*10000000,IF(I38="Thousand",H38*1000,"")))) -> 6300 | R38: =IF(G38="sqft",F38,IF(G38="sqyd",F38*9,IF(G38="acre",F38*43560,IF(G38="guntha",F38*1089,IF(G38="hectare",F38*107639.1,""))))) | S38: =IF(AND(P38="Resale",R38>0),Q38/R38,"") | W38: =COUNTIFS($M$2:$M$209,U38,$N$2:$N$209,V38,$P$2:$P$209,"Resale") -> 0 | X38: {=IFERROR(MEDIAN(_xlfn._xlws.FILTER($S$2:$S$209,($M$2:$M$209=U38)*($N$2:$N$209=V38)*($P$2:$P$209="Resale")*($S$2:$S$209<>""))),"")} | Y38: =IF(AND(P38="Long Term Rental",R38>0),Q38/R38,"") | Z38: =COUNTIFS($M$2:$M$209,U38,$P$2:$P$209,"Long Term Rental") -> 0 | AA38: {=IF(Z38=0,"",MEDIAN(_xlfn._xlws.FILTER($Y$2:$Y$209,($M$2:$M$209=U38)*($N$2:$N$209=V38)*($P$2:$P$209="Long Term Rental")*($Y$2:$Y$209<>""),"")))} | AB38: =IF(AND(V38="Villa",X38<>"",AA38<>""),(AA38*12/X38)*100,"") | AC38: {=IFERROR(MEDIAN(_xlfn._xlws.FILTER($Q$2:$Q$209,($M$2:$M$209=U38)*($P$2:$P$209="Short Term Rental")*($Q$2:$Q$209<>""))),"")}
A39: K0038 | B39: Two BHK Bungalow for weekend stay near Central Karjat | C39: Central Karjat | D39: Bungalow | E39: Two BHK | H39: 5000 | I39: INR | J39: Per Night | K39: Active | L39: Forward 60-day availability calendar; not a confirmed-stay record. | M39: =_xlfn.XLOOKUP(TRIM(C39),MAPPING!A:A,MAPPING!B:B,"CHECK") -> Karjat Town | N39: =_xlfn.XLOOKUP(D39,MAPPING!G:G,MAPPING!H:H,"CHECK") -> Villa | O39: =_xlfn.XLOOKUP(E39,MAPPING!J:J,MAPPING!K:K,"CHECK") -> 2 BHK | P39: =_xlfn.XLOOKUP(J39,MAPPING!M:M,MAPPING!N:N,"CHECK") -> Short Term Rental | Q39: =IF(I39="INR",H39,IF(I39="Lakh",H39*100000,IF(I39="Crore",H39*10000000,IF(I39="Thousand",H39*1000,"")))) -> 5000 | R39: =IF(G39="sqft",F39,IF(G39="sqyd",F39*9,IF(G39="acre",F39*43560,IF(G39="guntha",F39*1089,IF(G39="hectare",F39*107639.1,""))))) | S39: =IF(AND(P39="Resale",R39>0),Q39/R39,"") | W39: =COUNTIFS($M$2:$M$209,U39,$N$2:$N$209,V39,$P$2:$P$209,"Resale") -> 0 | X39: {=IFERROR(MEDIAN(_xlfn._xlws.FILTER($S$2:$S$209,($M$2:$M$209=U39)*($N$2:$N$209=V39)*($P$2:$P$209="Resale")*($S$2:$S$209<>""))),"")} | Y39: =IF(AND(P39="Long Term Rental",R39>0),Q39/R39,"") | Z39: =COUNTIFS($M$2:$M$209,U39,$P$2:$P$209,"Long Term Rental") -> 0 | AA39: {=IF(Z39=0,"",MEDIAN(_xlfn._xlws.FILTER($Y$2:$Y$209,($M$2:$M$209=U39)*($N$2:$N$209=V39)*($P$2:$P$209="Long Term Rental")*($Y$2:$Y$209<>""),"")))} | AB39: =IF(AND(V39="Villa",X39<>"",AA39<>""),(AA39*12/X39)*100,"") | AC39: {=IFERROR(MEDIAN(_xlfn._xlws.FILTER($Q$2:$Q$209,($M$2:$M$209=U39)*($P$2:$P$209="Short Term Rental")*($Q$2:$Q$209<>""))),"")}
A40: K0039 | B40: Two BHK Villa for weekend stay near Central Karjat | C40: Central Karjat | D40: Villa | E40: Two BHK | H40: 3700 | I40: INR | J40: Per Night | K40: Active | L40: Forward 60-day availability calendar; not a confirmed-stay record. | M40: =_xlfn.XLOOKUP(TRIM(C40),MAPPING!A:A,MAPPING!B:B,"CHECK") -> Karjat Town | N40: =_xlfn.XLOOKUP(D40,MAPPING!G:G,MAPPING!H:H,"CHECK") -> Villa | O40: =_xlfn.XLOOKUP(E40,MAPPING!J:J,MAPPING!K:K,"CHECK") -> 2 BHK | P40: =_xlfn.XLOOKUP(J40,MAPPING!M:M,MAPPING!N:N,"CHECK") -> Short Term Rental | Q40: =IF(I40="INR",H40,IF(I40="Lakh",H40*100000,IF(I40="Crore",H40*10000000,IF(I40="Thousand",H40*1000,"")))) -> 3700 | R40: =IF(G40="sqft",F40,IF(G40="sqyd",F40*9,IF(G40="acre",F40*43560,IF(G40="guntha",F40*1089,IF(G40="hectare",F40*107639.1,""))))) | S40: =IF(AND(P40="Resale",R40>0),Q40/R40,"") | W40: =COUNTIFS($M$2:$M$209,U40,$N$2:$N$209,V40,$P$2:$P$209,"Resale") -> 0 | X40: {=IFERROR(MEDIAN(_xlfn._xlws.FILTER($S$2:$S$209,($M$2:$M$209=U40)*($N$2:$N$209=V40)*($P$2:$P$209="Resale")*($S$2:$S$209<>""))),"")} | Y40: =IF(AND(P40="Long Term Rental",R40>0),Q40/R40,"") | Z40: =COUNTIFS($M$2:$M$209,U40,$P$2:$P$209,"Long Term Rental") -> 0 | AA40: {=IF(Z40=0,"",MEDIAN(_xlfn._xlws.FILTER($Y$2:$Y$209,($M$2:$M$209=U40)*($N$2:$N$209=V40)*($P$2:$P$209="Long Term Rental")*($Y$2:$Y$209<>""),"")))} | AB40: =IF(AND(V40="Villa",X40<>"",AA40<>""),(AA40*12/X40)*100,"") | AC40: {=IFERROR(MEDIAN(_xlfn._xlws.FILTER($Q$2:$Q$209,($M$2:$M$209=U40)*($P$2:$P$209="Short Term Rental")*($Q$2:$Q$209<>""))),"")}
A41: K0040 | B41: 3 BHK Bungalow for weekend stay near Karjat Town | C41: Karjat Town | D41: Bungalow | E41: 3 BHK | H41: 4300 | I41: INR | J41: Per Night | K41: Active | L41: Forward 60-day availability calendar; not a confirmed-stay record. | M41: =_xlfn.XLOOKUP(TRIM(C41),MAPPING!A:A,MAPPING!B:B,"CHECK") -> Karjat Town | N41: =_xlfn.XLOOKUP(D41,MAPPING!G:G,MAPPING!H:H,"CHECK") -> Villa | O41: =_xlfn.XLOOKUP(E41,MAPPING!J:J,MAPPING!K:K,"CHECK") -> 3 BHK | P41: =_xlfn.XLOOKUP(J41,MAPPING!M:M,MAPPING!N:N,"CHECK") -> Short Term Rental | Q41: =IF(I41="INR",H41,IF(I41="Lakh",H41*100000,IF(I41="Crore",H41*10000000,IF(I41="Thousand",H41*1000,"")))) -> 4300 | R41: =IF(G41="sqft",F41,IF(G41="sqyd",F41*9,IF(G41="acre",F41*43560,IF(G41="guntha",F41*1089,IF(G41="hectare",F41*107639.1,""))))) | S41: =IF(AND(P41="Resale",R41>0),Q41/R41,"") | W41: =COUNTIFS($M$2:$M$209,U41,$N$2:$N$209,V41,$P$2:$P$209,"Resale") -> 0 | X41: {=IFERROR(MEDIAN(_xlfn._xlws.FILTER($S$2:$S$209,($M$2:$M$209=U41)*($N$2:$N$209=V41)*($P$2:$P$209="Resale")*($S$2:$S$209<>""))),"")} | Y41: =IF(AND(P41="Long Term Rental",R41>0),Q41/R41,"") | Z41: =COUNTIFS($M$2:$M$209,U41,$P$2:$P$209,"Long Term Rental") -> 0 | AA41: {=IF(Z41=0,"",MEDIAN(_xlfn._xlws.FILTER($Y$2:$Y$209,($M$2:$M$209=U41)*($N$2:$N$209=V41)*($P$2:$P$209="Long Term Rental")*($Y$2:$Y$209<>""),"")))} | AB41: =IF(AND(V41="Villa",X41<>"",AA41<>""),(AA41*12/X41)*100,"") | AC41: {=IFERROR(MEDIAN(_xlfn._xlws.FILTER($Q$2:$Q$209,($M$2:$M$209=U41)*($P$2:$P$209="Short Term Rental")*($Q$2:$Q$209<>""))),"")}
A42: K0041 | B42: Two BHK Bungalow for weekend stay near Karjat | C42: Karjat | D42: Bungalow | E42: Two BHK | H42: 4700 | I42: INR | J42: Per Night | K42: Active | L42: Forward 60-day availability calendar; not a confirmed-stay record. | M42: =_xlfn.XLOOKUP(TRIM(C42),MAPPING!A:A,MAPPING!B:B,"CHECK") -> Karjat Town | N42: =_xlfn.XLOOKUP(D42,MAPPING!G:G,MAPPING!H:H,"CHECK") -> Villa | O42: =_xlfn.XLOOKUP(E42,MAPPING!J:J,MAPPING!K:K,"CHECK") -> 2 BHK | P42: =_xlfn.XLOOKUP(J42,MAPPING!M:M,MAPPING!N:N,"CHECK") -> Short Term Rental | Q42: =IF(I42="INR",H42,IF(I42="Lakh",H42*100000,IF(I42="Crore",H42*10000000,IF(I42="Thousand",H42*1000,"")))) -> 4700 | R42: =IF(G42="sqft",F42,IF(G42="sqyd",F42*9,IF(G42="acre",F42*43560,IF(G42="guntha",F42*1089,IF(G42="hectare",F42*107639.1,""))))) | S42: =IF(AND(P42="Resale",R42>0),Q42/R42,"") | W42: =COUNTIFS($M$2:$M$209,U42,$N$2:$N$209,V42,$P$2:$P$209,"Resale") -> 0 | X42: {=IFERROR(MEDIAN(_xlfn._xlws.FILTER($S$2:$S$209,($M$2:$M$209=U42)*($N$2:$N$209=V42)*($P$2:$P$209="Resale")*($S$2:$S$209<>""))),"")} | Y42: =IF(AND(P42="Long Term Rental",R42>0),Q42/R42,"") | Z42: =COUNTIFS($M$2:$M$209,U42,$P$2:$P$209,"Long Term Rental") -> 0 | AA42: {=IF(Z42=0,"",MEDIAN(_xlfn._xlws.FILTER($Y$2:$Y$209,($M$2:$M$209=U42)*($N$2:$N$209=V42)*($P$2:$P$209="Long Term Rental")*($Y$2:$Y$209<>""),"")))} | AB42: =IF(AND(V42="Villa",X42<>"",AA42<>""),(AA42*12/X42)*100,"") | AC42: {=IFERROR(MEDIAN(_xlfn._xlws.FILTER($Q$2:$Q$209,($M$2:$M$209=U42)*($P$2:$P$209="Short Term Rental")*($Q$2:$Q$209<>""))),"")}
A43: K0042 | B43: 3BR Bungalow for weekend stay near Karjat Station Road | C43: Karjat Station Road | D43: Bungalow | E43: 3BR | H43: 4400 | I43: INR | J43: Per Night | K43: Active | L43: Forward 60-day availability calendar; not a confirmed-stay record. | M43: =_xlfn.XLOOKUP(TRIM(C43),MAPPING!A:A,MAPPING!B:B,"CHECK") -> Karjat Town | N43: =_xlfn.XLOOKUP(D43,MAPPING!G:G,MAPPING!H:H,"CHECK") -> Villa | O43: =_xlfn.XLOOKUP(E43,MAPPING!J:J,MAPPING!K:K,"CHECK") -> 3 BHK | P43: =_xlfn.XLOOKUP(J43,MAPPING!M:M,MAPPING!N:N,"CHECK") -> Short Term Rental | Q43: =IF(I43="INR",H43,IF(I43="Lakh",H43*100000,IF(I43="Crore",H43*10000000,IF(I43="Thousand",H43*1000,"")))) -> 4400 | R43: =IF(G43="sqft",F43,IF(G43="sqyd",F43*9,IF(G43="acre",F43*43560,IF(G43="guntha",F43*1089,IF(G43="hectare",F43*107639.1,""))))) | S43: =IF(AND(P43="Resale",R43>0),Q43/R43,"") | W43: =COUNTIFS($M$2:$M$209,U43,$N$2:$N$209,V43,$P$2:$P$209,"Resale") -> 0 | X43: {=IFERROR(MEDIAN(_xlfn._xlws.FILTER($S$2:$S$209,($M$2:$M$209=U43)*($N$2:$N$209=V43)*($P$2:$P$209="Resale")*($S$2:$S$209<>""))),"")} | Y43: =IF(AND(P43="Long Term Rental",R43>0),Q43/R43,"") | Z43: =COUNTIFS($M$2:$M$209,U43,$P$2:$P$209,"Long Term Rental") -> 0 | AA43: {=IF(Z43=0,"",MEDIAN(_xlfn._xlws.FILTER($Y$2:$Y$209,($M$2:$M$209=U43)*($N$2:$N$209=V43)*($P$2:$P$209="Long Term Rental")*($Y$2:$Y$209<>""),"")))} | AB43: =IF(AND(V43="Villa",X43<>"",AA43<>""),(AA43*12/X43)*100,"") | AC43: {=IFERROR(MEDIAN(_xlfn._xlws.FILTER($Q$2:$Q$209,($M$2:$M$209=U43)*($P$2:$P$209="Short Term Rental")*($Q$2:$Q$209<>""))),"")}
A44: K0043 | B44: 3BHK Farmhouse for sale in Neral Rd | C44: Neral Rd | D44: Farmhouse | E44: 3BHK | F44: 3127 | G44: sqft | H44: 1.38 | I44: Crore | J44: One-time | K44: Active | M44: =_xlfn.XLOOKUP(TRIM(C44),MAPPING!A:A,MAPPING!B:B,"CHECK") -> Neral | N44: =_xlfn.XLOOKUP(D44,MAPPING!G:G,MAPPING!H:H,"CHECK") -> Villa | O44: =_xlfn.XLOOKUP(E44,MAPPING!J:J,MAPPING!K:K,"CHECK") -> 3 BHK | P44: =_xlfn.XLOOKUP(J44,MAPPING!M:M,MAPPING!N:N,"CHECK") -> Resale | Q44: =IF(I44="INR",H44,IF(I44="Lakh",H44*100000,IF(I44="Crore",H44*10000000,IF(I44="Thousand",H44*1000,"")))) -> 13800000 | R44: =IF(G44="sqft",F44,IF(G44="sqyd",F44*9,IF(G44="acre",F44*43560,IF(G44="guntha",F44*1089,IF(G44="hectare",F44*107639.1,""))))) -> 3127 | S44: =IF(AND(P44="Resale",R44>0),Q44/R44,"") -> 4413.1756 | W44: =COUNTIFS($M$2:$M$209,U44,$N$2:$N$209,V44,$P$2:$P$209,"Resale") -> 0 | X44: {=IFERROR(MEDIAN(_xlfn._xlws.FILTER($S$2:$S$209,($M$2:$M$209=U44)*($N$2:$N$209=V44)*($P$2:$P$209="Resale")*($S$2:$S$209<>""))),"")} | Y44: =IF(AND(P44="Long Term Rental",R44>0),Q44/R44,"") | Z44: =COUNTIFS($M$2:$M$209,U44,$P$2:$P$209,"Long Term Rental") -> 0 | AA44: {=IF(Z44=0,"",MEDIAN(_xlfn._xlws.FILTER($Y$2:$Y$209,($M$2:$M$209=U44)*($N$2:$N$209=V44)*($P$2:$P$209="Long Term Rental")*($Y$2:$Y$209<>""),"")))} | AB44: =IF(AND(V44="Villa",X44<>"",AA44<>""),(AA44*12/X44)*100,"") | AC44: {=IFERROR(MEDIAN(_xlfn._xlws.FILTER($Q$2:$Q$209,($M$2:$M$209=U44)*($P$2:$P$209="Short Term Rental")*($Q$2:$Q$209<>""))),"")}
A45: K0044 | B45: 4BHK Farmhouse for sale in Neral | C45: Neral | D45: Farmhouse | E45: 4BHK | F45: 2138 | G45: sqft | H45: 82.16 | I45: Lakh | J45: One-time | K45: Sold | M45: =_xlfn.XLOOKUP(TRIM(C45),MAPPING!A:A,MAPPING!B:B,"CHECK") -> Neral | N45: =_xlfn.XLOOKUP(D45,MAPPING!G:G,MAPPING!H:H,"CHECK") -> Villa | O45: =_xlfn.XLOOKUP(E45,MAPPING!J:J,MAPPING!K:K,"CHECK") -> 4 BHK | P45: =_xlfn.XLOOKUP(J45,MAPPING!M:M,MAPPING!N:N,"CHECK") -> Resale | Q45: =IF(I45="INR",H45,IF(I45="Lakh",H45*100000,IF(I45="Crore",H45*10000000,IF(I45="Thousand",H45*1000,"")))) -> 8216000 | R45: =IF(G45="sqft",F45,IF(G45="sqyd",F45*9,IF(G45="acre",F45*43560,IF(G45="guntha",F45*1089,IF(G45="hectare",F45*107639.1,""))))) -> 2138 | S45: =IF(AND(P45="Resale",R45>0),Q45/R45,"") -> 3842.8438 | W45: =COUNTIFS($M$2:$M$209,U45,$N$2:$N$209,V45,$P$2:$P$209,"Resale") -> 0 | X45: {=IFERROR(MEDIAN(_xlfn._xlws.FILTER($S$2:$S$209,($M$2:$M$209=U45)*($N$2:$N$209=V45)*($P$2:$P$209="Resale")*($S$2:$S$209<>""))),"")} | Y45: =IF(AND(P45="Long Term Rental",R45>0),Q45/R45,"") | Z45: =COUNTIFS($M$2:$M$209,U45,$P$2:$P$209,"Long Term Rental") -> 0 | AA45: {=IF(Z45=0,"",MEDIAN(_xlfn._xlws.FILTER($Y$2:$Y$209,($M$2:$M$209=U45)*($N$2:$N$209=V45)*($P$2:$P$209="Long Term Rental")*($Y$2:$Y$209<>""),"")))} | AB45: =IF(AND(V45="Villa",X45<>"",AA45<>""),(AA45*12/X45)*100,"") | AC45: {=IFERROR(MEDIAN(_xlfn._xlws.FILTER($Q$2:$Q$209,($M$2:$M$209=U45)*($P$2:$P$209="Short Term Rental")*($Q$2:$Q$209<>""))),"")}
...

Sheet MAPPING
A1: Raw Locality | B1: Micro Market | D1: Unique Raw Localities | G1: Raw_Asset_Type | H1: Asset_Class | J1: Raw_Configuration | K1: BHK_Configuration | M1: Vertical Evidence | N1: Vertical | P1: Unique Status
